2022-02-05 15:20:30,977 INFO    MainThread:25967 [internal.py:wandb_internal():89] W&B internal server running at pid: 25967, started at: 2022-02-05 15:20:30.977674
2022-02-05 15:20:30,979 DEBUG   HandlerThread:25967 [handler.py:handle_request():131] handle_request: check_version
2022-02-05 15:20:30,979 INFO    WriterThread:25967 [datastore.py:open_for_write():77] open: /home/yogender/Desktop/KaggleHousePricePrediction/RavirajMlOps/MLOps2/MLOps-Basics/week_7_ecr/outputs/2022-02-05/15-20-21/wandb/run-20220205_152030-thrnza52/run-thrnza52.wandb
2022-02-05 15:20:30,981 DEBUG   SenderThread:25967 [sender.py:send():235] send: header
2022-02-05 15:20:30,981 DEBUG   SenderThread:25967 [sender.py:send_request():249] send_request: check_version
2022-02-05 15:20:31,131 DEBUG   SenderThread:25967 [sender.py:send():235] send: run
2022-02-05 15:20:31,133 INFO    SenderThread:25967 [sender.py:_maybe_setup_resume():489] checking resume status for raviraja/MLOps Basics/thrnza52
2022-02-05 15:20:31,662 ERROR   SenderThread:25967 [internal_api.py:execute():143] 404 response executing GraphQL.
2022-02-05 15:20:31,662 ERROR   SenderThread:25967 [internal_api.py:execute():144] {"errors":[{"message":"project not found","path":["upsertBucket"]}],"data":{"upsertBucket":null}}
2022-02-05 15:20:32,131 INFO    WriterThread:25967 [datastore.py:close():281] close: /home/yogender/Desktop/KaggleHousePricePrediction/RavirajMlOps/MLOps2/MLOps-Basics/week_7_ecr/outputs/2022-02-05/15-20-21/wandb/run-20220205_152030-thrnza52/run-thrnza52.wandb
2022-02-05 15:20:32,132 INFO    HandlerThread:25967 [handler.py:finish():739] shutting down handler
2022-02-05 15:20:32,132 ERROR   MainThread:25967 [internal.py:wandb_internal():164] Thread SenderThread:
Traceback (most recent call last):
  File "/home/yogender/miniconda3/envs/MLOps/lib/python3.8/site-packages/wandb/sdk/lib/retry.py", line 102, in __call__
    result = self._call_fn(*args, **kwargs)
  File "/home/yogender/miniconda3/envs/MLOps/lib/python3.8/site-packages/wandb/sdk/internal/internal_api.py", line 146, in execute
    six.reraise(*sys.exc_info())
  File "/home/yogender/miniconda3/envs/MLOps/lib/python3.8/site-packages/six.py", line 719, in reraise
    raise value
  File "/home/yogender/miniconda3/envs/MLOps/lib/python3.8/site-packages/wandb/sdk/internal/internal_api.py", line 140, in execute
    return self.client.execute(*args, **kwargs)
  File "/home/yogender/miniconda3/envs/MLOps/lib/python3.8/site-packages/wandb/vendor/gql-0.2.0/gql/client.py", line 52, in execute
    result = self._get_result(document, *args, **kwargs)
  File "/home/yogender/miniconda3/envs/MLOps/lib/python3.8/site-packages/wandb/vendor/gql-0.2.0/gql/client.py", line 60, in _get_result
    return self.transport.execute(document, *args, **kwargs)
  File "/home/yogender/miniconda3/envs/MLOps/lib/python3.8/site-packages/wandb/vendor/gql-0.2.0/gql/transport/requests.py", line 39, in execute
    request.raise_for_status()
  File "/home/yogender/miniconda3/envs/MLOps/lib/python3.8/site-packages/requests/models.py", line 960, in raise_for_status
    raise HTTPError(http_error_msg, response=self)
requests.exceptions.HTTPError: 404 Client Error: Not Found for url: https://api.wandb.ai/graphql

During handling of the above exception, another exception occurred:

Traceback (most recent call last):
  File "/home/yogender/miniconda3/envs/MLOps/lib/python3.8/site-packages/wandb/apis/normalize.py", line 24, in wrapper
    return func(*args, **kwargs)
  File "/home/yogender/miniconda3/envs/MLOps/lib/python3.8/site-packages/wandb/sdk/internal/internal_api.py", line 1296, in upsert_run
    response = self.gql(mutation, variable_values=variable_values, **kwargs)
  File "/home/yogender/miniconda3/envs/MLOps/lib/python3.8/site-packages/wandb/sdk/lib/retry.py", line 118, in __call__
    if not check_retry_fn(e):
  File "/home/yogender/miniconda3/envs/MLOps/lib/python3.8/site-packages/wandb/util.py", line 821, in no_retry_auth
    raise CommError("Permission denied, ask the project owner to grant you access")
wandb.errors.CommError: Permission denied, ask the project owner to grant you access

During handling of the above exception, another exception occurred:

Traceback (most recent call last):
  File "/home/yogender/miniconda3/envs/MLOps/lib/python3.8/site-packages/wandb/sdk/internal/internal_util.py", line 54, in run
    self._run()
  File "/home/yogender/miniconda3/envs/MLOps/lib/python3.8/site-packages/wandb/sdk/internal/internal_util.py", line 105, in _run
    self._process(record)
  File "/home/yogender/miniconda3/envs/MLOps/lib/python3.8/site-packages/wandb/sdk/internal/internal.py", line 305, in _process
    self._sm.send(record)
  File "/home/yogender/miniconda3/envs/MLOps/lib/python3.8/site-packages/wandb/sdk/internal/sender.py", line 237, in send
    send_handler(record)
  File "/home/yogender/miniconda3/envs/MLOps/lib/python3.8/site-packages/wandb/sdk/internal/sender.py", line 692, in send_run
    self._init_run(run, config_value_dict)
  File "/home/yogender/miniconda3/envs/MLOps/lib/python3.8/site-packages/wandb/sdk/internal/sender.py", line 716, in _init_run
    server_run, inserted = self._api.upsert_run(
  File "/home/yogender/miniconda3/envs/MLOps/lib/python3.8/site-packages/wandb/apis/normalize.py", line 62, in wrapper
    six.reraise(CommError, CommError(message, err), sys.exc_info()[2])
  File "/home/yogender/miniconda3/envs/MLOps/lib/python3.8/site-packages/six.py", line 718, in reraise
    raise value.with_traceback(tb)
  File "/home/yogender/miniconda3/envs/MLOps/lib/python3.8/site-packages/wandb/apis/normalize.py", line 24, in wrapper
    return func(*args, **kwargs)
  File "/home/yogender/miniconda3/envs/MLOps/lib/python3.8/site-packages/wandb/sdk/internal/internal_api.py", line 1296, in upsert_run
    response = self.gql(mutation, variable_values=variable_values, **kwargs)
  File "/home/yogender/miniconda3/envs/MLOps/lib/python3.8/site-packages/wandb/sdk/lib/retry.py", line 118, in __call__
    if not check_retry_fn(e):
  File "/home/yogender/miniconda3/envs/MLOps/lib/python3.8/site-packages/wandb/util.py", line 821, in no_retry_auth
    raise CommError("Permission denied, ask the project owner to grant you access")
wandb.errors.CommError: Permission denied, ask the project owner to grant you access
2022-02-05 15:20:34,180 INFO    MainThread:25967 [internal.py:handle_exit():79] Internal process exited
